import { Injectable, NotFoundException } from '@nestjs/common';
import { InjectRepository } from '@nestjs/typeorm';
import { CreateTaskDto } from './dto/create-task.dto';
import { GetTasksFilterDto } from './dto/get-tasks-filter.dto';
import { TaskStatus } from './task-status.enum';
import { Task } from './task.entity';
import { TaskRepository } from './task.repository';

@Injectable()
export class TasksService {
  constructor(
    @InjectRepository(TaskRepository)
    private taskRepository: TaskRepository
  ) {}

  async getTasks(filterDto: GetTasksFilterDto): Promise<Task[]> {
    return this.taskRepository.getTasks(filterDto);
  }

  async getTaskById(id: number): Promise<Task> {
    const found = await this.taskRepository.findOne(id);    
    if (!found) throw new NotFoundException(`Task with ${id} not found`);     // üìùNestJS. We are not caught this exception in this scope, so the exception will scale up to the TaskController.getTaskById    
    return found;                                                             // TaskController.getTaskById are not caught the exception neither, so the exception scale up to the NestJS 
  }                                                                           // NestJS catch the exception and creates an HTTP Response accordingly

  async createTask(createTaskDto: CreateTaskDto): Promise<Task> {
    return this.taskRepository.createTask(createTaskDto);
  }

  async deleteTask(id: number): Promise<void> {
    const result = await this.taskRepository.delete(id);
    if (result.affected === 0) throw new NotFoundException(`Task with ${id} not found`);
  }

  async updateTaskStatus(id: number, status: TaskStatus): Promise<Task> {
    const task = await this.getTaskById(id);
    task.status = status;
    await task.save();
    return task;
  }

}
